[2025-03-10 10:55:55,747] INFO [django.utils.autoreload] Watching for file changes with StatReloader
[2025-03-10 11:32:11,556] INFO [django.utils.autoreload] E:\expense_tracker\expenses\views.py changed, reloading.
[2025-03-10 11:32:12,852] INFO [django.utils.autoreload] Watching for file changes with StatReloader
[2025-03-10 11:39:03,302] INFO [django.utils.autoreload] E:\expense_tracker\expense_tracker\settings.py changed, reloading.
[2025-03-10 11:39:05,100] INFO [django.utils.autoreload] Watching for file changes with StatReloader
[2025-03-10 11:39:09,991] INFO [django.utils.autoreload] E:\expense_tracker\expense_tracker\settings.py changed, reloading.
[2025-03-10 11:39:11,364] INFO [django.utils.autoreload] Watching for file changes with StatReloader
[2025-03-10 11:40:44,868] INFO [django.utils.autoreload] E:\expense_tracker\expense_tracker\urls.py changed, reloading.
[2025-03-10 11:40:46,044] INFO [django.utils.autoreload] Watching for file changes with StatReloader
[2025-03-10 11:41:24,904] WARNING [drf_yasg.inspectors.base] view's ExpenseDetailView raised exception during schema generation; use `getattr(self, 'swagger_fake_view', False)` to detect and short-circuit this
Traceback (most recent call last):
  File "E:\expense_tracker\venv\Lib\site-packages\django\db\models\fields\__init__.py", line 2123, in get_prep_value
    return int(value)
           ^^^^^^^^^^
  File "E:\expense_tracker\venv\Lib\site-packages\django\contrib\auth\models.py", line 438, in __int__
    raise TypeError(
TypeError: Cannot cast AnonymousUser to int. Are you trying to use it in place of User?

The above exception was the direct cause of the following exception:

Traceback (most recent call last):
  File "E:\expense_tracker\venv\Lib\site-packages\drf_yasg\inspectors\base.py", line 42, in call_view_method
    return view_method()
           ^^^^^^^^^^^^^
  File "E:\expense_tracker\expenses\views.py", line 81, in get_queryset
    return Expense.objects.filter(user=self.request.user)
           ^^^^^^^^^^^^^^^^^^^^^^^^^^^^^^^^^^^^^^^^^^^^^^
  File "E:\expense_tracker\venv\Lib\site-packages\django\db\models\manager.py", line 87, in manager_method
    return getattr(self.get_queryset(), name)(*args, **kwargs)
           ^^^^^^^^^^^^^^^^^^^^^^^^^^^^^^^^^^^^^^^^^^^^^^^^^^^
  File "E:\expense_tracker\venv\Lib\site-packages\django\db\models\query.py", line 1476, in filter
    return self._filter_or_exclude(False, args, kwargs)
           ^^^^^^^^^^^^^^^^^^^^^^^^^^^^^^^^^^^^^^^^^^^^
  File "E:\expense_tracker\venv\Lib\site-packages\django\db\models\query.py", line 1494, in _filter_or_exclude
    clone._filter_or_exclude_inplace(negate, args, kwargs)
  File "E:\expense_tracker\venv\Lib\site-packages\django\db\models\query.py", line 1501, in _filter_or_exclude_inplace
    self._query.add_q(Q(*args, **kwargs))
  File "E:\expense_tracker\venv\Lib\site-packages\django\db\models\sql\query.py", line 1609, in add_q
    clause, _ = self._add_q(q_object, self.used_aliases)
                ^^^^^^^^^^^^^^^^^^^^^^^^^^^^^^^^^^^^^^^^
  File "E:\expense_tracker\venv\Lib\site-packages\django\db\models\sql\query.py", line 1641, in _add_q
    child_clause, needed_inner = self.build_filter(
                                 ^^^^^^^^^^^^^^^^^^
  File "E:\expense_tracker\venv\Lib\site-packages\django\db\models\sql\query.py", line 1555, in build_filter
    condition = self.build_lookup(lookups, col, value)
                ^^^^^^^^^^^^^^^^^^^^^^^^^^^^^^^^^^^^^^
  File "E:\expense_tracker\venv\Lib\site-packages\django\db\models\sql\query.py", line 1385, in build_lookup
    lookup = lookup_class(lhs, rhs)
             ^^^^^^^^^^^^^^^^^^^^^^
  File "E:\expense_tracker\venv\Lib\site-packages\django\db\models\lookups.py", line 30, in __init__
    self.rhs = self.get_prep_lookup()
               ^^^^^^^^^^^^^^^^^^^^^^
  File "E:\expense_tracker\venv\Lib\site-packages\django\db\models\fields\related_lookups.py", line 156, in get_prep_lookup
    self.rhs = target_field.get_prep_value(self.rhs)
               ^^^^^^^^^^^^^^^^^^^^^^^^^^^^^^^^^^^^^
  File "E:\expense_tracker\venv\Lib\site-packages\django\db\models\fields\__init__.py", line 2125, in get_prep_value
    raise e.__class__(
TypeError: Field 'id' expected a number but got <django.contrib.auth.models.AnonymousUser object at 0x000001F3F25F29F0>.
[2025-03-10 11:41:25,127] WARNING [drf_yasg.inspectors.base] view's ExpenseDetailView raised exception during schema generation; use `getattr(self, 'swagger_fake_view', False)` to detect and short-circuit this
Traceback (most recent call last):
  File "E:\expense_tracker\venv\Lib\site-packages\django\db\models\fields\__init__.py", line 2123, in get_prep_value
    return int(value)
           ^^^^^^^^^^
  File "E:\expense_tracker\venv\Lib\site-packages\django\contrib\auth\models.py", line 438, in __int__
    raise TypeError(
TypeError: Cannot cast AnonymousUser to int. Are you trying to use it in place of User?

The above exception was the direct cause of the following exception:

Traceback (most recent call last):
  File "E:\expense_tracker\venv\Lib\site-packages\drf_yasg\inspectors\base.py", line 42, in call_view_method
    return view_method()
           ^^^^^^^^^^^^^
  File "E:\expense_tracker\expenses\views.py", line 81, in get_queryset
    return Expense.objects.filter(user=self.request.user)
           ^^^^^^^^^^^^^^^^^^^^^^^^^^^^^^^^^^^^^^^^^^^^^^
  File "E:\expense_tracker\venv\Lib\site-packages\django\db\models\manager.py", line 87, in manager_method
    return getattr(self.get_queryset(), name)(*args, **kwargs)
           ^^^^^^^^^^^^^^^^^^^^^^^^^^^^^^^^^^^^^^^^^^^^^^^^^^^
  File "E:\expense_tracker\venv\Lib\site-packages\django\db\models\query.py", line 1476, in filter
    return self._filter_or_exclude(False, args, kwargs)
           ^^^^^^^^^^^^^^^^^^^^^^^^^^^^^^^^^^^^^^^^^^^^
  File "E:\expense_tracker\venv\Lib\site-packages\django\db\models\query.py", line 1494, in _filter_or_exclude
    clone._filter_or_exclude_inplace(negate, args, kwargs)
  File "E:\expense_tracker\venv\Lib\site-packages\django\db\models\query.py", line 1501, in _filter_or_exclude_inplace
    self._query.add_q(Q(*args, **kwargs))
  File "E:\expense_tracker\venv\Lib\site-packages\django\db\models\sql\query.py", line 1609, in add_q
    clause, _ = self._add_q(q_object, self.used_aliases)
                ^^^^^^^^^^^^^^^^^^^^^^^^^^^^^^^^^^^^^^^^
  File "E:\expense_tracker\venv\Lib\site-packages\django\db\models\sql\query.py", line 1641, in _add_q
    child_clause, needed_inner = self.build_filter(
                                 ^^^^^^^^^^^^^^^^^^
  File "E:\expense_tracker\venv\Lib\site-packages\django\db\models\sql\query.py", line 1555, in build_filter
    condition = self.build_lookup(lookups, col, value)
                ^^^^^^^^^^^^^^^^^^^^^^^^^^^^^^^^^^^^^^
  File "E:\expense_tracker\venv\Lib\site-packages\django\db\models\sql\query.py", line 1385, in build_lookup
    lookup = lookup_class(lhs, rhs)
             ^^^^^^^^^^^^^^^^^^^^^^
  File "E:\expense_tracker\venv\Lib\site-packages\django\db\models\lookups.py", line 30, in __init__
    self.rhs = self.get_prep_lookup()
               ^^^^^^^^^^^^^^^^^^^^^^
  File "E:\expense_tracker\venv\Lib\site-packages\django\db\models\fields\related_lookups.py", line 156, in get_prep_lookup
    self.rhs = target_field.get_prep_value(self.rhs)
               ^^^^^^^^^^^^^^^^^^^^^^^^^^^^^^^^^^^^^
  File "E:\expense_tracker\venv\Lib\site-packages\django\db\models\fields\__init__.py", line 2125, in get_prep_value
    raise e.__class__(
TypeError: Field 'id' expected a number but got <django.contrib.auth.models.AnonymousUser object at 0x000001F3F25F29F0>.
[2025-03-10 11:41:25,127] WARNING [drf_yasg.inspectors.base] view's ExpenseDetailView raised exception during schema generation; use `getattr(self, 'swagger_fake_view', False)` to detect and short-circuit this
Traceback (most recent call last):
  File "E:\expense_tracker\venv\Lib\site-packages\django\db\models\fields\__init__.py", line 2123, in get_prep_value
    return int(value)
           ^^^^^^^^^^
  File "E:\expense_tracker\venv\Lib\site-packages\django\contrib\auth\models.py", line 438, in __int__
    raise TypeError(
TypeError: Cannot cast AnonymousUser to int. Are you trying to use it in place of User?

The above exception was the direct cause of the following exception:

Traceback (most recent call last):
  File "E:\expense_tracker\venv\Lib\site-packages\drf_yasg\inspectors\base.py", line 42, in call_view_method
    return view_method()
           ^^^^^^^^^^^^^
  File "E:\expense_tracker\expenses\views.py", line 81, in get_queryset
    return Expense.objects.filter(user=self.request.user)
           ^^^^^^^^^^^^^^^^^^^^^^^^^^^^^^^^^^^^^^^^^^^^^^
  File "E:\expense_tracker\venv\Lib\site-packages\django\db\models\manager.py", line 87, in manager_method
    return getattr(self.get_queryset(), name)(*args, **kwargs)
           ^^^^^^^^^^^^^^^^^^^^^^^^^^^^^^^^^^^^^^^^^^^^^^^^^^^
  File "E:\expense_tracker\venv\Lib\site-packages\django\db\models\query.py", line 1476, in filter
    return self._filter_or_exclude(False, args, kwargs)
           ^^^^^^^^^^^^^^^^^^^^^^^^^^^^^^^^^^^^^^^^^^^^
  File "E:\expense_tracker\venv\Lib\site-packages\django\db\models\query.py", line 1494, in _filter_or_exclude
    clone._filter_or_exclude_inplace(negate, args, kwargs)
  File "E:\expense_tracker\venv\Lib\site-packages\django\db\models\query.py", line 1501, in _filter_or_exclude_inplace
    self._query.add_q(Q(*args, **kwargs))
  File "E:\expense_tracker\venv\Lib\site-packages\django\db\models\sql\query.py", line 1609, in add_q
    clause, _ = self._add_q(q_object, self.used_aliases)
                ^^^^^^^^^^^^^^^^^^^^^^^^^^^^^^^^^^^^^^^^
  File "E:\expense_tracker\venv\Lib\site-packages\django\db\models\sql\query.py", line 1641, in _add_q
    child_clause, needed_inner = self.build_filter(
                                 ^^^^^^^^^^^^^^^^^^
  File "E:\expense_tracker\venv\Lib\site-packages\django\db\models\sql\query.py", line 1555, in build_filter
    condition = self.build_lookup(lookups, col, value)
                ^^^^^^^^^^^^^^^^^^^^^^^^^^^^^^^^^^^^^^
  File "E:\expense_tracker\venv\Lib\site-packages\django\db\models\sql\query.py", line 1385, in build_lookup
    lookup = lookup_class(lhs, rhs)
             ^^^^^^^^^^^^^^^^^^^^^^
  File "E:\expense_tracker\venv\Lib\site-packages\django\db\models\lookups.py", line 30, in __init__
    self.rhs = self.get_prep_lookup()
               ^^^^^^^^^^^^^^^^^^^^^^
  File "E:\expense_tracker\venv\Lib\site-packages\django\db\models\fields\related_lookups.py", line 156, in get_prep_lookup
    self.rhs = target_field.get_prep_value(self.rhs)
               ^^^^^^^^^^^^^^^^^^^^^^^^^^^^^^^^^^^^^
  File "E:\expense_tracker\venv\Lib\site-packages\django\db\models\fields\__init__.py", line 2125, in get_prep_value
    raise e.__class__(
TypeError: Field 'id' expected a number but got <django.contrib.auth.models.AnonymousUser object at 0x000001F3F25F29F0>.
[2025-03-10 11:41:25,127] WARNING [drf_yasg.inspectors.base] view's ExpenseDetailView raised exception during schema generation; use `getattr(self, 'swagger_fake_view', False)` to detect and short-circuit this
Traceback (most recent call last):
  File "E:\expense_tracker\venv\Lib\site-packages\django\db\models\fields\__init__.py", line 2123, in get_prep_value
    return int(value)
           ^^^^^^^^^^
  File "E:\expense_tracker\venv\Lib\site-packages\django\contrib\auth\models.py", line 438, in __int__
    raise TypeError(
TypeError: Cannot cast AnonymousUser to int. Are you trying to use it in place of User?

The above exception was the direct cause of the following exception:

Traceback (most recent call last):
  File "E:\expense_tracker\venv\Lib\site-packages\drf_yasg\inspectors\base.py", line 42, in call_view_method
    return view_method()
           ^^^^^^^^^^^^^
  File "E:\expense_tracker\expenses\views.py", line 81, in get_queryset
    return Expense.objects.filter(user=self.request.user)
           ^^^^^^^^^^^^^^^^^^^^^^^^^^^^^^^^^^^^^^^^^^^^^^
  File "E:\expense_tracker\venv\Lib\site-packages\django\db\models\manager.py", line 87, in manager_method
    return getattr(self.get_queryset(), name)(*args, **kwargs)
           ^^^^^^^^^^^^^^^^^^^^^^^^^^^^^^^^^^^^^^^^^^^^^^^^^^^
  File "E:\expense_tracker\venv\Lib\site-packages\django\db\models\query.py", line 1476, in filter
    return self._filter_or_exclude(False, args, kwargs)
           ^^^^^^^^^^^^^^^^^^^^^^^^^^^^^^^^^^^^^^^^^^^^
  File "E:\expense_tracker\venv\Lib\site-packages\django\db\models\query.py", line 1494, in _filter_or_exclude
    clone._filter_or_exclude_inplace(negate, args, kwargs)
  File "E:\expense_tracker\venv\Lib\site-packages\django\db\models\query.py", line 1501, in _filter_or_exclude_inplace
    self._query.add_q(Q(*args, **kwargs))
  File "E:\expense_tracker\venv\Lib\site-packages\django\db\models\sql\query.py", line 1609, in add_q
    clause, _ = self._add_q(q_object, self.used_aliases)
                ^^^^^^^^^^^^^^^^^^^^^^^^^^^^^^^^^^^^^^^^
  File "E:\expense_tracker\venv\Lib\site-packages\django\db\models\sql\query.py", line 1641, in _add_q
    child_clause, needed_inner = self.build_filter(
                                 ^^^^^^^^^^^^^^^^^^
  File "E:\expense_tracker\venv\Lib\site-packages\django\db\models\sql\query.py", line 1555, in build_filter
    condition = self.build_lookup(lookups, col, value)
                ^^^^^^^^^^^^^^^^^^^^^^^^^^^^^^^^^^^^^^
  File "E:\expense_tracker\venv\Lib\site-packages\django\db\models\sql\query.py", line 1385, in build_lookup
    lookup = lookup_class(lhs, rhs)
             ^^^^^^^^^^^^^^^^^^^^^^
  File "E:\expense_tracker\venv\Lib\site-packages\django\db\models\lookups.py", line 30, in __init__
    self.rhs = self.get_prep_lookup()
               ^^^^^^^^^^^^^^^^^^^^^^
  File "E:\expense_tracker\venv\Lib\site-packages\django\db\models\fields\related_lookups.py", line 156, in get_prep_lookup
    self.rhs = target_field.get_prep_value(self.rhs)
               ^^^^^^^^^^^^^^^^^^^^^^^^^^^^^^^^^^^^^
  File "E:\expense_tracker\venv\Lib\site-packages\django\db\models\fields\__init__.py", line 2125, in get_prep_value
    raise e.__class__(
TypeError: Field 'id' expected a number but got <django.contrib.auth.models.AnonymousUser object at 0x000001F3F25F29F0>.
[2025-03-10 11:43:51,238] INFO [accounts.views] Login failed: {'username': [ErrorDetail(string='This field is required.', code='required')], 'password': [ErrorDetail(string='This field is required.', code='required')]}
[2025-03-10 11:45:47,010] INFO [accounts.views] Login failed: {'username': [ErrorDetail(string='This field is required.', code='required')], 'password': [ErrorDetail(string='This field is required.', code='required')]}
[2025-03-10 11:46:54,570] WARNING [drf_yasg.inspectors.base] view's ExpenseDetailView raised exception during schema generation; use `getattr(self, 'swagger_fake_view', False)` to detect and short-circuit this
Traceback (most recent call last):
  File "E:\expense_tracker\venv\Lib\site-packages\django\db\models\fields\__init__.py", line 2123, in get_prep_value
    return int(value)
           ^^^^^^^^^^
  File "E:\expense_tracker\venv\Lib\site-packages\django\contrib\auth\models.py", line 438, in __int__
    raise TypeError(
TypeError: Cannot cast AnonymousUser to int. Are you trying to use it in place of User?

The above exception was the direct cause of the following exception:

Traceback (most recent call last):
  File "E:\expense_tracker\venv\Lib\site-packages\drf_yasg\inspectors\base.py", line 42, in call_view_method
    return view_method()
           ^^^^^^^^^^^^^
  File "E:\expense_tracker\expenses\views.py", line 81, in get_queryset
    return Expense.objects.filter(user=self.request.user)
           ^^^^^^^^^^^^^^^^^^^^^^^^^^^^^^^^^^^^^^^^^^^^^^
  File "E:\expense_tracker\venv\Lib\site-packages\django\db\models\manager.py", line 87, in manager_method
    return getattr(self.get_queryset(), name)(*args, **kwargs)
           ^^^^^^^^^^^^^^^^^^^^^^^^^^^^^^^^^^^^^^^^^^^^^^^^^^^
  File "E:\expense_tracker\venv\Lib\site-packages\django\db\models\query.py", line 1476, in filter
    return self._filter_or_exclude(False, args, kwargs)
           ^^^^^^^^^^^^^^^^^^^^^^^^^^^^^^^^^^^^^^^^^^^^
  File "E:\expense_tracker\venv\Lib\site-packages\django\db\models\query.py", line 1494, in _filter_or_exclude
    clone._filter_or_exclude_inplace(negate, args, kwargs)
  File "E:\expense_tracker\venv\Lib\site-packages\django\db\models\query.py", line 1501, in _filter_or_exclude_inplace
    self._query.add_q(Q(*args, **kwargs))
  File "E:\expense_tracker\venv\Lib\site-packages\django\db\models\sql\query.py", line 1609, in add_q
    clause, _ = self._add_q(q_object, self.used_aliases)
                ^^^^^^^^^^^^^^^^^^^^^^^^^^^^^^^^^^^^^^^^
  File "E:\expense_tracker\venv\Lib\site-packages\django\db\models\sql\query.py", line 1641, in _add_q
    child_clause, needed_inner = self.build_filter(
                                 ^^^^^^^^^^^^^^^^^^
  File "E:\expense_tracker\venv\Lib\site-packages\django\db\models\sql\query.py", line 1555, in build_filter
    condition = self.build_lookup(lookups, col, value)
                ^^^^^^^^^^^^^^^^^^^^^^^^^^^^^^^^^^^^^^
  File "E:\expense_tracker\venv\Lib\site-packages\django\db\models\sql\query.py", line 1385, in build_lookup
    lookup = lookup_class(lhs, rhs)
             ^^^^^^^^^^^^^^^^^^^^^^
  File "E:\expense_tracker\venv\Lib\site-packages\django\db\models\lookups.py", line 30, in __init__
    self.rhs = self.get_prep_lookup()
               ^^^^^^^^^^^^^^^^^^^^^^
  File "E:\expense_tracker\venv\Lib\site-packages\django\db\models\fields\related_lookups.py", line 156, in get_prep_lookup
    self.rhs = target_field.get_prep_value(self.rhs)
               ^^^^^^^^^^^^^^^^^^^^^^^^^^^^^^^^^^^^^
  File "E:\expense_tracker\venv\Lib\site-packages\django\db\models\fields\__init__.py", line 2125, in get_prep_value
    raise e.__class__(
TypeError: Field 'id' expected a number but got <django.contrib.auth.models.AnonymousUser object at 0x000001F3F27086B0>.
[2025-03-10 11:46:54,589] WARNING [drf_yasg.inspectors.base] view's ExpenseDetailView raised exception during schema generation; use `getattr(self, 'swagger_fake_view', False)` to detect and short-circuit this
Traceback (most recent call last):
  File "E:\expense_tracker\venv\Lib\site-packages\django\db\models\fields\__init__.py", line 2123, in get_prep_value
    return int(value)
           ^^^^^^^^^^
  File "E:\expense_tracker\venv\Lib\site-packages\django\contrib\auth\models.py", line 438, in __int__
    raise TypeError(
TypeError: Cannot cast AnonymousUser to int. Are you trying to use it in place of User?

The above exception was the direct cause of the following exception:

Traceback (most recent call last):
  File "E:\expense_tracker\venv\Lib\site-packages\drf_yasg\inspectors\base.py", line 42, in call_view_method
    return view_method()
           ^^^^^^^^^^^^^
  File "E:\expense_tracker\expenses\views.py", line 81, in get_queryset
    return Expense.objects.filter(user=self.request.user)
           ^^^^^^^^^^^^^^^^^^^^^^^^^^^^^^^^^^^^^^^^^^^^^^
  File "E:\expense_tracker\venv\Lib\site-packages\django\db\models\manager.py", line 87, in manager_method
    return getattr(self.get_queryset(), name)(*args, **kwargs)
           ^^^^^^^^^^^^^^^^^^^^^^^^^^^^^^^^^^^^^^^^^^^^^^^^^^^
  File "E:\expense_tracker\venv\Lib\site-packages\django\db\models\query.py", line 1476, in filter
    return self._filter_or_exclude(False, args, kwargs)
           ^^^^^^^^^^^^^^^^^^^^^^^^^^^^^^^^^^^^^^^^^^^^
  File "E:\expense_tracker\venv\Lib\site-packages\django\db\models\query.py", line 1494, in _filter_or_exclude
    clone._filter_or_exclude_inplace(negate, args, kwargs)
  File "E:\expense_tracker\venv\Lib\site-packages\django\db\models\query.py", line 1501, in _filter_or_exclude_inplace
    self._query.add_q(Q(*args, **kwargs))
  File "E:\expense_tracker\venv\Lib\site-packages\django\db\models\sql\query.py", line 1609, in add_q
    clause, _ = self._add_q(q_object, self.used_aliases)
                ^^^^^^^^^^^^^^^^^^^^^^^^^^^^^^^^^^^^^^^^
  File "E:\expense_tracker\venv\Lib\site-packages\django\db\models\sql\query.py", line 1641, in _add_q
    child_clause, needed_inner = self.build_filter(
                                 ^^^^^^^^^^^^^^^^^^
  File "E:\expense_tracker\venv\Lib\site-packages\django\db\models\sql\query.py", line 1555, in build_filter
    condition = self.build_lookup(lookups, col, value)
                ^^^^^^^^^^^^^^^^^^^^^^^^^^^^^^^^^^^^^^
  File "E:\expense_tracker\venv\Lib\site-packages\django\db\models\sql\query.py", line 1385, in build_lookup
    lookup = lookup_class(lhs, rhs)
             ^^^^^^^^^^^^^^^^^^^^^^
  File "E:\expense_tracker\venv\Lib\site-packages\django\db\models\lookups.py", line 30, in __init__
    self.rhs = self.get_prep_lookup()
               ^^^^^^^^^^^^^^^^^^^^^^
  File "E:\expense_tracker\venv\Lib\site-packages\django\db\models\fields\related_lookups.py", line 156, in get_prep_lookup
    self.rhs = target_field.get_prep_value(self.rhs)
               ^^^^^^^^^^^^^^^^^^^^^^^^^^^^^^^^^^^^^
  File "E:\expense_tracker\venv\Lib\site-packages\django\db\models\fields\__init__.py", line 2125, in get_prep_value
    raise e.__class__(
TypeError: Field 'id' expected a number but got <django.contrib.auth.models.AnonymousUser object at 0x000001F3F27086B0>.
[2025-03-10 11:46:54,589] WARNING [drf_yasg.inspectors.base] view's ExpenseDetailView raised exception during schema generation; use `getattr(self, 'swagger_fake_view', False)` to detect and short-circuit this
Traceback (most recent call last):
  File "E:\expense_tracker\venv\Lib\site-packages\django\db\models\fields\__init__.py", line 2123, in get_prep_value
    return int(value)
           ^^^^^^^^^^
  File "E:\expense_tracker\venv\Lib\site-packages\django\contrib\auth\models.py", line 438, in __int__
    raise TypeError(
TypeError: Cannot cast AnonymousUser to int. Are you trying to use it in place of User?

The above exception was the direct cause of the following exception:

Traceback (most recent call last):
  File "E:\expense_tracker\venv\Lib\site-packages\drf_yasg\inspectors\base.py", line 42, in call_view_method
    return view_method()
           ^^^^^^^^^^^^^
  File "E:\expense_tracker\expenses\views.py", line 81, in get_queryset
    return Expense.objects.filter(user=self.request.user)
           ^^^^^^^^^^^^^^^^^^^^^^^^^^^^^^^^^^^^^^^^^^^^^^
  File "E:\expense_tracker\venv\Lib\site-packages\django\db\models\manager.py", line 87, in manager_method
    return getattr(self.get_queryset(), name)(*args, **kwargs)
           ^^^^^^^^^^^^^^^^^^^^^^^^^^^^^^^^^^^^^^^^^^^^^^^^^^^
  File "E:\expense_tracker\venv\Lib\site-packages\django\db\models\query.py", line 1476, in filter
    return self._filter_or_exclude(False, args, kwargs)
           ^^^^^^^^^^^^^^^^^^^^^^^^^^^^^^^^^^^^^^^^^^^^
  File "E:\expense_tracker\venv\Lib\site-packages\django\db\models\query.py", line 1494, in _filter_or_exclude
    clone._filter_or_exclude_inplace(negate, args, kwargs)
  File "E:\expense_tracker\venv\Lib\site-packages\django\db\models\query.py", line 1501, in _filter_or_exclude_inplace
    self._query.add_q(Q(*args, **kwargs))
  File "E:\expense_tracker\venv\Lib\site-packages\django\db\models\sql\query.py", line 1609, in add_q
    clause, _ = self._add_q(q_object, self.used_aliases)
                ^^^^^^^^^^^^^^^^^^^^^^^^^^^^^^^^^^^^^^^^
  File "E:\expense_tracker\venv\Lib\site-packages\django\db\models\sql\query.py", line 1641, in _add_q
    child_clause, needed_inner = self.build_filter(
                                 ^^^^^^^^^^^^^^^^^^
  File "E:\expense_tracker\venv\Lib\site-packages\django\db\models\sql\query.py", line 1555, in build_filter
    condition = self.build_lookup(lookups, col, value)
                ^^^^^^^^^^^^^^^^^^^^^^^^^^^^^^^^^^^^^^
  File "E:\expense_tracker\venv\Lib\site-packages\django\db\models\sql\query.py", line 1385, in build_lookup
    lookup = lookup_class(lhs, rhs)
             ^^^^^^^^^^^^^^^^^^^^^^
  File "E:\expense_tracker\venv\Lib\site-packages\django\db\models\lookups.py", line 30, in __init__
    self.rhs = self.get_prep_lookup()
               ^^^^^^^^^^^^^^^^^^^^^^
  File "E:\expense_tracker\venv\Lib\site-packages\django\db\models\fields\related_lookups.py", line 156, in get_prep_lookup
    self.rhs = target_field.get_prep_value(self.rhs)
               ^^^^^^^^^^^^^^^^^^^^^^^^^^^^^^^^^^^^^
  File "E:\expense_tracker\venv\Lib\site-packages\django\db\models\fields\__init__.py", line 2125, in get_prep_value
    raise e.__class__(
TypeError: Field 'id' expected a number but got <django.contrib.auth.models.AnonymousUser object at 0x000001F3F27086B0>.
[2025-03-10 11:46:54,601] WARNING [drf_yasg.inspectors.base] view's ExpenseDetailView raised exception during schema generation; use `getattr(self, 'swagger_fake_view', False)` to detect and short-circuit this
Traceback (most recent call last):
  File "E:\expense_tracker\venv\Lib\site-packages\django\db\models\fields\__init__.py", line 2123, in get_prep_value
    return int(value)
           ^^^^^^^^^^
  File "E:\expense_tracker\venv\Lib\site-packages\django\contrib\auth\models.py", line 438, in __int__
    raise TypeError(
TypeError: Cannot cast AnonymousUser to int. Are you trying to use it in place of User?

The above exception was the direct cause of the following exception:

Traceback (most recent call last):
  File "E:\expense_tracker\venv\Lib\site-packages\drf_yasg\inspectors\base.py", line 42, in call_view_method
    return view_method()
           ^^^^^^^^^^^^^
  File "E:\expense_tracker\expenses\views.py", line 81, in get_queryset
    return Expense.objects.filter(user=self.request.user)
           ^^^^^^^^^^^^^^^^^^^^^^^^^^^^^^^^^^^^^^^^^^^^^^
  File "E:\expense_tracker\venv\Lib\site-packages\django\db\models\manager.py", line 87, in manager_method
    return getattr(self.get_queryset(), name)(*args, **kwargs)
           ^^^^^^^^^^^^^^^^^^^^^^^^^^^^^^^^^^^^^^^^^^^^^^^^^^^
  File "E:\expense_tracker\venv\Lib\site-packages\django\db\models\query.py", line 1476, in filter
    return self._filter_or_exclude(False, args, kwargs)
           ^^^^^^^^^^^^^^^^^^^^^^^^^^^^^^^^^^^^^^^^^^^^
  File "E:\expense_tracker\venv\Lib\site-packages\django\db\models\query.py", line 1494, in _filter_or_exclude
    clone._filter_or_exclude_inplace(negate, args, kwargs)
  File "E:\expense_tracker\venv\Lib\site-packages\django\db\models\query.py", line 1501, in _filter_or_exclude_inplace
    self._query.add_q(Q(*args, **kwargs))
  File "E:\expense_tracker\venv\Lib\site-packages\django\db\models\sql\query.py", line 1609, in add_q
    clause, _ = self._add_q(q_object, self.used_aliases)
                ^^^^^^^^^^^^^^^^^^^^^^^^^^^^^^^^^^^^^^^^
  File "E:\expense_tracker\venv\Lib\site-packages\django\db\models\sql\query.py", line 1641, in _add_q
    child_clause, needed_inner = self.build_filter(
                                 ^^^^^^^^^^^^^^^^^^
  File "E:\expense_tracker\venv\Lib\site-packages\django\db\models\sql\query.py", line 1555, in build_filter
    condition = self.build_lookup(lookups, col, value)
                ^^^^^^^^^^^^^^^^^^^^^^^^^^^^^^^^^^^^^^
  File "E:\expense_tracker\venv\Lib\site-packages\django\db\models\sql\query.py", line 1385, in build_lookup
    lookup = lookup_class(lhs, rhs)
             ^^^^^^^^^^^^^^^^^^^^^^
  File "E:\expense_tracker\venv\Lib\site-packages\django\db\models\lookups.py", line 30, in __init__
    self.rhs = self.get_prep_lookup()
               ^^^^^^^^^^^^^^^^^^^^^^
  File "E:\expense_tracker\venv\Lib\site-packages\django\db\models\fields\related_lookups.py", line 156, in get_prep_lookup
    self.rhs = target_field.get_prep_value(self.rhs)
               ^^^^^^^^^^^^^^^^^^^^^^^^^^^^^^^^^^^^^
  File "E:\expense_tracker\venv\Lib\site-packages\django\db\models\fields\__init__.py", line 2125, in get_prep_value
    raise e.__class__(
TypeError: Field 'id' expected a number but got <django.contrib.auth.models.AnonymousUser object at 0x000001F3F27086B0>.
[2025-03-10 11:49:52,134] INFO [accounts.views] Login failed: {'non_field_errors': [ErrorDetail(string='Wrong credentials.', code='invalid')]}
[2025-03-10 11:49:52,149] INFO [accounts.views] Login failed: {'username': [ErrorDetail(string='This field is required.', code='required')]}
[2025-03-10 11:49:54,244] INFO [accounts.views] Registration failed: {'email': [ErrorDetail(string='This field is required.', code='required')]}
[2025-03-10 11:49:54,261] INFO [accounts.views] Registration failed: {'password': [ErrorDetail(string="Password fields didn't match.", code='invalid')]}
[2025-03-10 11:53:39,954] INFO [django.utils.autoreload] E:\expense_tracker\expenses\views.py changed, reloading.
